2018-03-23 16:14:02,954 test_002.py[line: 25] INFO: False is not true
2018-03-23 16:14:02,954 test_002.py[line: 25] INFO: False is not true
2018-03-23 16:14:02,955 test_add.py[line: 13] INFO: -----test start add ------
2018-03-23 16:14:02,955 test_add.py[line: 13] INFO: -----test start add ------
2018-03-23 16:14:02,955 test_add.py[line: 15] INFO: -----test end add---------
2018-03-23 16:14:02,955 test_add.py[line: 15] INFO: -----test end add---------
2018-03-23 16:31:12,514 test_002.py[line: 25] INFO: False is not true
2018-03-23 16:31:12,514 test_002.py[line: 25] INFO: False is not true
2018-03-23 16:31:12,515 test_add.py[line: 13] INFO: -----test start add ------
2018-03-23 16:31:12,515 test_add.py[line: 13] INFO: -----test start add ------
2018-03-23 16:31:12,515 test_add.py[line: 15] INFO: -----test end add---------
2018-03-23 16:31:12,515 test_add.py[line: 15] INFO: -----test end add---------
2018-03-23 17:47:49,070 home.py[line: 41] INFO: HTTPSConnectionPool(host='mydev.100szy.com', port=443): Max retries exceeded with url: /apipc/?v=pc1.0.0&c=user&a=is_login (Caused by SSLError(SSLError(1, '[SSL: CERTIFICATE_VERIFY_FAILED] certificate verify failed (_ssl.c:646)'),))
2018-03-23 17:52:34,015 home.py[line: 41] INFO: HTTPSConnectionPool(host='mydev.100szy.com', port=443): Max retries exceeded with url: /apipc/?v=pc1.0.0&c=user&a=is_login (Caused by SSLError(SSLError(1, '[SSL: CERTIFICATE_VERIFY_FAILED] certificate verify failed (_ssl.c:646)'),))
